Exception on /upload [POST]
Traceback (most recent call last):
  File "C:\Users\Philip\Documents\programmieren\python\filessafe\filessafe\venv\lib\site-packages\flask\app.py", line 2077, in wsgi_app
    response = self.full_dispatch_request()
  File "C:\Users\Philip\Documents\programmieren\python\filessafe\filessafe\venv\lib\site-packages\flask\app.py", line 1526, in full_dispatch_request
    return self.finalize_request(rv)
  File "C:\Users\Philip\Documents\programmieren\python\filessafe\filessafe\venv\lib\site-packages\flask\app.py", line 1545, in finalize_request
    response = self.make_response(rv)
  File "C:\Users\Philip\Documents\programmieren\python\filessafe\filessafe\venv\lib\site-packages\flask\app.py", line 1701, in make_response
    raise TypeError(
TypeError: The view function for 'upload' did not return a valid response. The function either returned None or ended without a return statement.
Exception on /upload [POST]
Traceback (most recent call last):
  File "C:\Users\Philip\Documents\programmieren\python\filessafe\filessafe\venv\lib\site-packages\flask\app.py", line 2077, in wsgi_app
    response = self.full_dispatch_request()
  File "C:\Users\Philip\Documents\programmieren\python\filessafe\filessafe\venv\lib\site-packages\flask\app.py", line 1525, in full_dispatch_request
    rv = self.handle_user_exception(e)
  File "C:\Users\Philip\Documents\programmieren\python\filessafe\filessafe\venv\lib\site-packages\flask\app.py", line 1523, in full_dispatch_request
    rv = self.dispatch_request()
  File "C:\Users\Philip\Documents\programmieren\python\filessafe\filessafe\venv\lib\site-packages\flask\app.py", line 1509, in dispatch_request
    return self.ensure_sync(self.view_functions[rule.endpoint])(**req.view_args)
  File "C:\Users\Philip\Documents\programmieren\python\filessafe\filessafe\app\routes.py", line 23, in upload
    if db.session.get(file_id):
TypeError: get() missing 1 required positional argument: 'ident'
Exception on /upload [POST]
Traceback (most recent call last):
  File "C:\Users\Philip\Documents\programmieren\python\filessafe\filessafe\venv\lib\site-packages\flask\app.py", line 2077, in wsgi_app
    response = self.full_dispatch_request()
  File "C:\Users\Philip\Documents\programmieren\python\filessafe\filessafe\venv\lib\site-packages\flask\app.py", line 1525, in full_dispatch_request
    rv = self.handle_user_exception(e)
  File "C:\Users\Philip\Documents\programmieren\python\filessafe\filessafe\venv\lib\site-packages\flask\app.py", line 1523, in full_dispatch_request
    rv = self.dispatch_request()
  File "C:\Users\Philip\Documents\programmieren\python\filessafe\filessafe\venv\lib\site-packages\flask\app.py", line 1509, in dispatch_request
    return self.ensure_sync(self.view_functions[rule.endpoint])(**req.view_args)
  File "C:\Users\Philip\Documents\programmieren\python\filessafe\filessafe\app\routes.py", line 23, in upload
    if File.query.get(file_id):
  File "<string>", line 2, in get
  File "C:\Users\Philip\Documents\programmieren\python\filessafe\filessafe\venv\lib\site-packages\sqlalchemy\util\deprecations.py", line 402, in warned
    return fn(*args, **kwargs)
  File "C:\Users\Philip\Documents\programmieren\python\filessafe\filessafe\venv\lib\site-packages\sqlalchemy\orm\query.py", line 943, in get
    return self._get_impl(ident, loading.load_on_pk_identity)
  File "C:\Users\Philip\Documents\programmieren\python\filessafe\filessafe\venv\lib\site-packages\sqlalchemy\orm\query.py", line 947, in _get_impl
    return self.session._get_impl(
  File "C:\Users\Philip\Documents\programmieren\python\filessafe\filessafe\venv\lib\site-packages\sqlalchemy\orm\session.py", line 2912, in _get_impl
    return db_load_fn(
  File "C:\Users\Philip\Documents\programmieren\python\filessafe\filessafe\venv\lib\site-packages\sqlalchemy\orm\loading.py", line 530, in load_on_pk_identity
    session.execute(
  File "C:\Users\Philip\Documents\programmieren\python\filessafe\filessafe\venv\lib\site-packages\sqlalchemy\orm\session.py", line 1712, in execute
    result = conn._execute_20(statement, params or {}, execution_options)
  File "C:\Users\Philip\Documents\programmieren\python\filessafe\filessafe\venv\lib\site-packages\sqlalchemy\engine\base.py", line 1631, in _execute_20
    return meth(self, args_10style, kwargs_10style, execution_options)
  File "C:\Users\Philip\Documents\programmieren\python\filessafe\filessafe\venv\lib\site-packages\sqlalchemy\sql\elements.py", line 332, in _execute_on_connection
    return connection._execute_clauseelement(
  File "C:\Users\Philip\Documents\programmieren\python\filessafe\filessafe\venv\lib\site-packages\sqlalchemy\engine\base.py", line 1498, in _execute_clauseelement
    ret = self._execute_context(
  File "C:\Users\Philip\Documents\programmieren\python\filessafe\filessafe\venv\lib\site-packages\sqlalchemy\engine\base.py", line 1862, in _execute_context
    self._handle_dbapi_exception(
  File "C:\Users\Philip\Documents\programmieren\python\filessafe\filessafe\venv\lib\site-packages\sqlalchemy\engine\base.py", line 2047, in _handle_dbapi_exception
    util.raise_(exc_info[1], with_traceback=exc_info[2])
  File "C:\Users\Philip\Documents\programmieren\python\filessafe\filessafe\venv\lib\site-packages\sqlalchemy\util\compat.py", line 208, in raise_
    raise exception
  File "C:\Users\Philip\Documents\programmieren\python\filessafe\filessafe\venv\lib\site-packages\sqlalchemy\engine\base.py", line 1819, in _execute_context
    self.dialect.do_execute(
  File "C:\Users\Philip\Documents\programmieren\python\filessafe\filessafe\venv\lib\site-packages\sqlalchemy\engine\default.py", line 732, in do_execute
    cursor.execute(statement, parameters)
OverflowError: Python int too large to convert to SQLite INTEGER
Exception on /upload [POST]
Traceback (most recent call last):
  File "C:\Users\Philip\Documents\programmieren\python\filessafe\filessafe\venv\lib\site-packages\flask\app.py", line 2077, in wsgi_app
    response = self.full_dispatch_request()
  File "C:\Users\Philip\Documents\programmieren\python\filessafe\filessafe\venv\lib\site-packages\flask\app.py", line 1525, in full_dispatch_request
    rv = self.handle_user_exception(e)
  File "C:\Users\Philip\Documents\programmieren\python\filessafe\filessafe\venv\lib\site-packages\flask\app.py", line 1523, in full_dispatch_request
    rv = self.dispatch_request()
  File "C:\Users\Philip\Documents\programmieren\python\filessafe\filessafe\venv\lib\site-packages\flask\app.py", line 1509, in dispatch_request
    return self.ensure_sync(self.view_functions[rule.endpoint])(**req.view_args)
  File "C:\Users\Philip\Documents\programmieren\python\filessafe\filessafe\app\routes.py", line 23, in upload
    if File.query.get(file_id):
  File "<string>", line 2, in get
  File "C:\Users\Philip\Documents\programmieren\python\filessafe\filessafe\venv\lib\site-packages\sqlalchemy\util\deprecations.py", line 402, in warned
    return fn(*args, **kwargs)
  File "C:\Users\Philip\Documents\programmieren\python\filessafe\filessafe\venv\lib\site-packages\sqlalchemy\orm\query.py", line 943, in get
    return self._get_impl(ident, loading.load_on_pk_identity)
  File "C:\Users\Philip\Documents\programmieren\python\filessafe\filessafe\venv\lib\site-packages\sqlalchemy\orm\query.py", line 947, in _get_impl
    return self.session._get_impl(
  File "C:\Users\Philip\Documents\programmieren\python\filessafe\filessafe\venv\lib\site-packages\sqlalchemy\orm\session.py", line 2912, in _get_impl
    return db_load_fn(
  File "C:\Users\Philip\Documents\programmieren\python\filessafe\filessafe\venv\lib\site-packages\sqlalchemy\orm\loading.py", line 530, in load_on_pk_identity
    session.execute(
  File "C:\Users\Philip\Documents\programmieren\python\filessafe\filessafe\venv\lib\site-packages\sqlalchemy\orm\session.py", line 1712, in execute
    result = conn._execute_20(statement, params or {}, execution_options)
  File "C:\Users\Philip\Documents\programmieren\python\filessafe\filessafe\venv\lib\site-packages\sqlalchemy\engine\base.py", line 1631, in _execute_20
    return meth(self, args_10style, kwargs_10style, execution_options)
  File "C:\Users\Philip\Documents\programmieren\python\filessafe\filessafe\venv\lib\site-packages\sqlalchemy\sql\elements.py", line 332, in _execute_on_connection
    return connection._execute_clauseelement(
  File "C:\Users\Philip\Documents\programmieren\python\filessafe\filessafe\venv\lib\site-packages\sqlalchemy\engine\base.py", line 1498, in _execute_clauseelement
    ret = self._execute_context(
  File "C:\Users\Philip\Documents\programmieren\python\filessafe\filessafe\venv\lib\site-packages\sqlalchemy\engine\base.py", line 1862, in _execute_context
    self._handle_dbapi_exception(
  File "C:\Users\Philip\Documents\programmieren\python\filessafe\filessafe\venv\lib\site-packages\sqlalchemy\engine\base.py", line 2047, in _handle_dbapi_exception
    util.raise_(exc_info[1], with_traceback=exc_info[2])
  File "C:\Users\Philip\Documents\programmieren\python\filessafe\filessafe\venv\lib\site-packages\sqlalchemy\util\compat.py", line 208, in raise_
    raise exception
  File "C:\Users\Philip\Documents\programmieren\python\filessafe\filessafe\venv\lib\site-packages\sqlalchemy\engine\base.py", line 1819, in _execute_context
    self.dialect.do_execute(
  File "C:\Users\Philip\Documents\programmieren\python\filessafe\filessafe\venv\lib\site-packages\sqlalchemy\engine\default.py", line 732, in do_execute
    cursor.execute(statement, parameters)
OverflowError: Python int too large to convert to SQLite INTEGER
